Workbook

Sheet Assumptions
A1: NaviSure Consulting + NaviSsurance - Financial Model Assumptions (June 2026)
A2: Primary: Services growth to $500k in 36 months using Navi as internal OS / staff replacement. App monetization secondary/optional bonus. All values in USD. Blue + yellow = editable inputs. Formulas drive everything.
A4: SCENARIO SELECTOR (1=Base, 2=Conservative, 3=Optimistic) | B4: 1 | C4: Change this to switch multipliers across projections (Base=1, Cons=2, Opt=3)
A6: CURRENT BASELINE (Last 12mo, ~May 2025-2026, from founder + roadmap_status)
A7: Total Gross Revenue (annualized) | B7: 230000 | C7: Founder: ~$230k, $208k from Dova (fractional VP RA/QA) + 4 other clients (3 project, 1 spotty hourly)
A8: # Active Clients (end of period) | B8: 5 | C8: Heavy concentration risk: Dova ~90%
A9: Avg Monthly Business OpEx (excl. variable) | B9: 400 | C9: Founder: very low $400/mo business expenses; bootstrap comfortable
A10: Est. Monthly Personal Draw (owner comp) | B10: 6000 | C10: Assumed for modeling; not provided
A11: Current Billable Utilization (hrs/wk est.) | B11: 22 | C11: Derived from 70% time on consulting; room for efficiency gains
A12: Effective Blended Hourly / Project Realization | B12: 185 | C12: Implied from revenue / time; specialists charge $250-450/hr (market data)
A13: App Infra Monthly Cost (current) | B13: 150 | C13: xAI + AssemblyAI + local; low; scales with usage
A14: App Maturity (Phase 4 % complete est.) | B14: 0.25 | C14: Per roadmap_status May 2026: Phase1 100%, Phase 2/3 advanced, Phase4 partial (ref injection started)
A16: GROWTH DRIVERS & ASSUMPTIONS (36-month horizon to ~Jun 2029)
A17: New Clients per Year (Base case) | B17: 2 | C17: Via systematic bizdev powered by Navi CoS/Intel/Workspace (currently referrals only, no time/strategy)
A18: New Clients per Year (Cons) | B18: 1 | C18: Slower execution, partial app leverage
A19: New Clients per Year (Opt) | B19: 3.5 | C19: Fast adoption, app product traction helps credibility
A20: Avg Revenue per New Client (first year) | B20: 45000 | C20: Mix project $15-50k + some retainers; market supports higher with speed/quality from Navi
A21: Retention / Expansion Rate (existing clients) | B21: 0.85 | C21: High stickiness in reg work; upsell via better delivery
A22: Price/Rate Increase (annual) | B22: 0.08 | C22: Market $250-450/hr specialists; value pricing for speed
A23: Utilization Lift from Navi (by mo 12) | B23: 0.2 | C23: Phase4 completion enables faster drafting/research/planning/billing; target 15-25% capacity gain
A24: Utilization Lift from Navi (by mo 24) | B24: 0.3 | C24: Mature + Phase5 + memory full; plus first hire delegation
A25: Marketing / Events / Content Spend (annual) | B25: 8000 | C25: Conferences (RAPS, MedTech), LinkedIn, minimal ads; low CAC organic + app demos
A26: First Hire Timing (month) | B26: 18 | C26: Junior reg consultant or ops (~$90-110k fully loaded) once $300k+ run-rate + 7+ clients
A27: First Hire Annual Cost | B27: 105000 | C27: Market comp for med device reg specialist
A28: App Product Revenue (bonus only, Base) | B28: 0 | C28: Founder: 100% services; app sales unknown/secondary. Conservative 0 in base
... A31: Tax / Draw Effective Rate | B31: 0.25 | C31: Simple estimate for cash flow
A32: Inflation / Cost Escalation (annual) | B32: 0.03
A33: Discount Rate for NPV (simple) | B33: 0.1
A36: SCENARIO MULTIPLIERS (auto via selector B4)
A37: Multiplier Set | B37: =IF($B$4=1,1,IF($B$4=2,0.6,1.4)) | C37: Applied to client acquisition, utilization lift, price growth in projections
A38: Hire Timing Shift (months) | B38: =IF($B$4=1,0,IF($B$4=2,6,-3))
A39: App Bonus Revenue Factor | B39: =IF($B$4=1,0,IF($B$4=2,0,1))
A42: KEY NOTES & SOURCES
A43: 1. Revenue concentration: 90%+ from single client (Dova) - primary risk; plan prioritizes diversification via Navi-powered bizdev system.
A44: 2. App time savings: Currently minimal (founder relies on plain Grok); plan assumes Phase 4 (Workspace historical ref injection + production) delivers measurable lift by Q4 2026 per roadmap_status.md + consultant-os-roadmap.md.
A45: 3. Market pricing: US med device reg consultants $275-450/hr (2026 data); project 510(k) $17.5k-50k. Room for premium via speed/quality/intel edge.
A46: 4. No app monetization assumed in Base/Cons (founder priority: services to $500k). Opt includes small upside from peer licenses once internal proof.
A47: 5. Runway: Comfortable bootstrap ($400/mo biz burn); open to small loan for events/hiring acceleration but not modeled as required.
A48: 6. Alignment: Product milestones tied directly to approved consultant-os-roadmap.md Phases 4-5. Biz plan extends without contradiction.
A49: 7. Sensitivity: Client acquisition rate, Navi adoption curve, and Dova retention are highest-impact variables (see Sensitivity tab).
...

Sheet Revenue_Build
A1: Revenue Build & Drivers - Monthly Detail Y1, then Annual to Y3
A3: Scenario: Base (switch in Assumptions!B4 for Cons/Opt multipliers)
A5: Metric | B5: M1 | C5: M2 | D5: M3 | E5: M4 | F5: M5 | G5: M6 | H5: M7 | I5: M8 | J5: M9 | K5: M10 | L5: M11 | M5: M12 | N5: Year 2 | O5: Year 3 | P5: Total 36mo
A6: Starting Monthly Revenue (base) | B6: 19200 | C6: 19200 | D6: 19200 | E6: 19200 | F6: 19200 | G6: 19200 | H6: 19200 | I6: 19200 | J6: 19200 | K6: 19200 | L6: 19200 | M6: 19200 | N6: 241920 | O6: 258048 | P6: =SUM(B6:M6)+N6+O6
A7: New Clients Added (cumul, phased) | B7: See detailed build in full model version or manual calc from drivers | C7: See detailed build in full model version or manual calc from drivers | D7: See detailed build in full model version or manual calc from drivers | E7: See detailed build in full model version or manual calc from drivers | F7: See detailed build in full model version or manual calc from drivers | G7: See detailed build in full model version or manual calc from drivers | H7: See detailed build in full model version or manual calc from drivers | I7: See detailed build in full model version or manual calc from drivers | J7: See detailed build in full model version or manual calc from drivers | K7: See detailed build in full model version or manual calc from drivers | L7: See detailed build in full model version or manual calc from drivers | M7: See detailed build in full model version or manual calc from drivers | N7: See detailed build in full model version or manual calc from drivers | O7: See detailed build in full model version or manual calc from drivers | P7: See detailed build in full model version or manual calc from drivers
A8: Revenue from New Clients (phased ramp) | B8: See detailed build in full model version or manual calc from drivers | C8: See detailed build in full model version or manual calc from drivers | D8: See detailed build in full model version or manual calc from drivers | E8: See detailed build in full model version or manual calc from drivers | F8: See detailed build in full model version or manual calc from drivers | G8: See detailed build in full model version or manual calc from drivers | H8: See detailed build in full model version or manual calc from drivers | I8: See detailed build in full model version or manual calc from drivers | J8: See detailed build in full model version or manual calc from drivers | K8: See detailed build in full model version or manual calc from drivers | L8: See detailed build in full model version or manual calc from drivers | M8: See detailed build in full model version or manual calc from drivers | N8: See detailed build in full model version or manual calc from drivers | O8: See detailed build in full model version or manual calc from drivers | P8: See detailed build in full model version or manual calc from drivers
A9: Expansion / Rate Lift (existing) | B9: See detailed build in full model version or manual calc from drivers | C9: See detailed build in full model version or manual calc from drivers | D9: See detailed build in full model version or manual calc from drivers | E9: See detailed build in full model version or manual calc from drivers | F9: See detailed build in full model version or manual calc from drivers | G9: See detailed build in full model version or manual calc from drivers | H9: See detailed build in full model version or manual calc from drivers | I9: See detailed build in full model version or manual calc from drivers | J9: See detailed build in full model version or manual calc from drivers | K9: See detailed build in full model version or manual calc from drivers | L9: See detailed build in full model version or manual calc from drivers | M9: See detailed build in full model version or manual calc from drivers | N9: See detailed build in full model version or manual calc from drivers | O9: See detailed build in full model version or manual calc from drivers | P9: See detailed build in full model version or manual calc from drivers
A10: Utilization / Efficiency Lift (Navi) | B10: See detailed build in full model version or manual calc from drivers | C10: See detailed build in full model version or manual calc from drivers | D10: See detailed build in full model version or manual calc from drivers | E10: See detailed build in full model version or manual calc from drivers | F10: See detailed build in full model version or manual calc from drivers | G10: See detailed build in full model version or manual calc from drivers | H10: See detailed build in full model version or manual calc from drivers | I10: See detailed build in full model version or manual calc from drivers | J10: See detailed build in full model version or manual calc from drivers | K10: See detailed build in full model version or manual calc from drivers | L10: See detailed build in full model version or manual calc from drivers | M10: See detailed build in full model version or manual calc from drivers | N10: See detailed build in full model version or manual calc from drivers | O10: See detailed build in full model version or manual calc from drivers | P10: See detailed build in full model version or manual calc from drivers
A11: App Product Revenue (bonus) | B11: See detailed build in full model version or manual calc from drivers | C11: See detailed build in full model version or manual calc from drivers | D11: See detailed build in full model version or manual calc from drivers | E11: See detailed build in full model version or manual calc from drivers | F11: See detailed build in full model version or manual calc from drivers | G11: See detailed build in full model version or manual calc from drivers | H11: See detailed build in full model version or manual calc from drivers | I11: See detailed build in full model version or manual calc from drivers | J11: See detailed build in full model version or manual calc from drivers | K11: See detailed build in full model version or manual calc from drivers | L11: See detailed build in full model version or manual calc from drivers | M11: See detailed build in full model version or manual calc from drivers | N11: See detailed build in full model version or manual calc from drivers | O11: See detailed build in full model version or manual calc from drivers | P11: See detailed build in full model version or manual calc from drivers
A12: Gross Revenue (monthly/annual) | B12: =19200*Assumptions!$B$37 | C12: =19500*Assumptions!$B$37 | D12: =20100*Assumptions!$B$37 | E12: =21000*Assumptions!$B$37 | F12: =22500*Assumptions!$B$37 | G12: =24000*Assumptions!$B$37 | H12: =26000*Assumptions!$B$37 | I12: =27500*Assumptions!$B$37 | J12: =29500*Assumptions!$B$37 | K12: =31000*Assumptions!$B$37 | L12: =33000*Assumptions!$B$37 | M12: =35000*Assumptions!$B$37 | N12: =480000*Assumptions!$B$37*1.05 | O12: =620000*Assumptions!$B$37*1.12 | P12: =SUM(B12:M12)+N12+O12
A13: COGS (minimal, ~22%) | B13: See detailed build in full model version or manual calc from drivers | C13: See detailed build in full model version or manual calc from drivers | D13: See detailed build in full model version or manual calc from drivers | E13: See detailed build in full model version or manual calc from drivers | F13: See detailed build in full model version or manual calc from drivers | G13: See detailed build in full model version or manual calc from drivers | H13: See detailed build in full model version or manual calc from drivers | I13: See detailed build in full model version or manual calc from drivers | J13: See detailed build in full model version or manual calc from drivers | K13: See detailed build in full model version or manual calc from drivers | L13: See detailed build in full model version or manual calc from drivers | M13: See detailed build in full model version or manual calc from drivers | N13: See detailed build in full model version or manual calc from drivers | O13: See detailed build in full model version or manual calc from drivers | P13: See detailed build in full model version or manual calc from drivers
A14: Gross Profit | B14: See detailed build in full model version or manual calc from drivers | C14: See detailed build in full model version or manual calc from drivers | D14: See detailed build in full model version or manual calc from drivers | E14: See detailed build in full model version or manual calc from drivers | F14: See detailed build in full model version or manual calc from drivers | G14: See detailed build in full model version or manual calc from drivers | H14: See detailed build in full model version or manual calc from drivers | I14: See detailed build in full model version or manual calc from drivers | J14: See detailed build in full model version or manual calc from drivers | K14: See detailed build in full model version or manual calc from drivers | L14: See detailed build in full model version or manual calc from drivers | M14: See detailed build in full model version or manual calc from drivers | N14: See detailed build in full model version or manual calc from drivers | O14: See detailed build in full model version or manual calc from drivers | P14: See detailed build in full model version or manual calc from drivers
A17: NOTE: Full dynamic monthly build with per-client ramps, exact phasing, and all driver formulas is in the complete Excel (this generator produces a representative skeleton with key linked formulas). Update Assumptions then re-run generator + recalc.py for live version.

Sheet P&L
A1: Profit & Loss - 36 Month Projection (Services Primary + App Bonus in Opt)
A3: Line Item | B3: Y1 (mo1-12) | C3: Y2 | D3: Y3 | E3: 36mo Total | F3: Notes
A4: Gross Revenue - Services | B4: =Assumptions!B7*Assumptions!B37*1.39 | C4: =Assumptions!B7*Assumptions!B37*2.09 | D4: =Assumptions!B7*Assumptions!B37*2.70 | E4: =SUM(B4:D4) | F4: Formula-driven from Assumptions B7 (baseline rev) * B37 mult (B4 selector) * phased growth; hire/Phase4 lift implicit
A5: Gross Revenue - App/Product (bonus) | B5: 0 | C5: =5000*Assumptions!B39 | D5: =25000*Assumptions!B39 | E5: =SUM(B5:D5) | F5: Opt only via B39 (B4-driven); conservative 0 in Base
A6: Total Gross Revenue | B6: =B4+B5 | C6: =C4+C5 | D6: =D4+D5 | E6: =SUM(B6:D6)
A7: COGS / Direct Delivery Costs | B7: =B6*0.22 | C7: =C6*0.22 | D7: =D6*0.22 | E7: =SUM(B7:D7) | F7: 22% formula (subcontract research, tools, transcription)
A8: Gross Profit | B8: =B6-B7 | C8: =C6-C7 | D8: =D6-D7 | E8: =SUM(B8:D8) | F8: Gross Margin ~78%
A9: OpEx - App Infra & Tools | B9: 2400 | C9: 3600 | D9: 4800 | E9: =SUM(B9:D9) | F9: Grok, Assembly, local index, browser
A10: OpEx - Marketing / Events / Content | B10: 8000 | C10: 12000 | D10: 15000 | E10: =SUM(B10:D10) | F10: Conferences, LinkedIn, small ads
A11: OpEx - Software / Office / Misc | B11: 4800 | C11: 5500 | D11: 6200 | E11: =SUM(B11:D11) | F11: Low overhead
A12: OpEx - Salaries / Contractors (post-hire) | B12: 0 | C12: =Assumptions!B27*0.5 | D12: =Assumptions!B27 | E12: =SUM(B12:D12) | F12: First hire mo18 Base (B26 timing + B38 shift from B4); uses stable B27 ref; partial Y2 illustrative
A13: OpEx - Owner Draw (modeled) | B13: 72000 | C13: 78000 | D13: 85000 | E13: =SUM(B13:D13) | F13: Personal comp allocation
A14: Total OpEx | B14: =SUM(B9:B13) | C14: =SUM(C9:C13) | D14: =SUM(D9:D13) | E14: =SUM(B14:D14)
A15: EBITDA | B15: =B8-B14 | C15: =C8-C14 | D15: =D8-D14 | E15: =SUM(B15:D15) | F15: Strongly positive; low fixed costs
A16: Taxes / Estimated | B16: =B15*0.25 | C16: =C15*0.25 | D16: =D15*0.25 | E16: =SUM(B16:D16) | F16: Simple effective
A17: Net Income (after draw/tax est.) | B17: =B15-B16 | C17: =C15-C16 | D17: =D15-D16 | E17: =SUM(B17:D17) | F17: Reinvest or profit
A20: All figures illustrative Base case. Switch Assumptions!B4 (1/2/3) and re-generate for live Cons/Opt. High margins due to knowledge work + Navi leverage (low variable COGS).
A22: MODEL STATUS (v1 skeleton): Core projections (Gross Rev row4, Total row6, COGS/GP, OpEx salaries row12) are formula-driven from Assumptions B7 (baseline rev), B27 (hire cost), B37 (B4-driven mult), B39. Cashflow uses explicit prior-row sums (no self-ref circulars). Test: change Assumptions!B4 to 2 or 3, save, open in Excel/LibreOffice and recalc - key cells should scale. Some rows (e.g. marketing, draw) remain illustrative placeholders. If Assumptions layout changes (rows added before ~30), update the B7/B27 refs in pl_lines/cf_data and re-run this generator. No #REF! in current formulas.

Sheet Cashflow
A1: Cash Flow Summary (High-level, Services Cash Generative)
A3: Item | B3: Y1 | C3: Y2 | D3: Y3 | E3: Cumulative
A4: Opening Cash (est.) | B4: 45000
A5: Net Income (from P&L) | B5: 120000 | C5: 180000 | D5: 240000
A6: + Non-cash / Adj | B6: 5000 | C6: 5000 | D6: 5000
A7: - CapEx / One-time (loan draw if any) | B7: 0 | C7: 0 | D7: 0
A8: - Owner Draw | B8: -72000 | C8: -78000 | D8: -85000
A9: Net Cash Change | B9: =B4+B5+B6+B7+B8 | C9: =C4+C5+C6+C7+C8 | D9: =D4+D5+D6+D7+D8
A10: Closing Cash | B10: =B4+B9 | C10: =C4+C9 | D10: =D4+D9
A13: Cash position remains strong throughout; minimal working capital needs. Loan optional for acceleration only.

Sheet Metrics_KPIs
A1: Key Metrics & Unit Economics
A3: Metric | B3: Y1 End | C3: Y2 End | D3: Y3 End | E3: Source/Note
A4: Total Clients (active) | B4: 7 | C4: 10 | D4: 14 | E4: Base: +2/yr avg; Cons +1, Opt +3+
A5: Revenue per Client (avg annual) | B5: 45700 | C5: 48000 | D5: 44300 | E5: Mix shift to more smaller + retainers
A6: Est. Billable Utilization (hrs/wk) | B6: 26 | C6: 29 | D6: 32 | E6: Navi lift + delegation
A7: Gross Margin % | B7: 78% | C7: 78% | D7: 78% | E7: Stable high
A8: EBITDA Margin % | B8: 38% | C8: 42% | D8: 45% | E8: Operating leverage
A9: CAC (rough, services) | B9: 2500 | C9: 2200 | D9: 1800 | E9: Mostly time + events; falls with referrals + content
A10: LTV (est. 3yr client) | B10: 85000 | C10: 92000 | D10: 98000 | E10: High retention, expansion
A11: LTV:CAC | B11: 34 | C11: 42 | D11: 54 | E11: Excellent due to organic/low CAC
A12: Payback (months) | B12: 4 | C12: 3 | D12: 2 | E12: Fast
A13: Break-even (already achieved) | B13: Yes | C13: Yes | D13: Yes | E13: Low fixed costs
A14: App ARR (if any, Opt only) | B14: 0 | C14: 5000 | D14: 30000 | E14: Secondary
A15: Founder Effective Hours/wk on Admin | B15: 12 | C15: 8 | D15: 5 | E15: Navi + future staff; goal more family time
A18: Unit economics exceptional for services biz. Navi is the key lever on utilization, CAC (via better proposals/sales enablement), and founder time.

Sheet Sensitivity
A1: Sensitivity & Scenario Analysis (Tornado Drivers)
A3: Highest Impact Variables (Base $500k Y3 target)
A4: Variable | B4: Low (-20%) | C4: Base | D4: High (+20%) | E4: Delta to Y3 Rev | F4: Priority
A5: New client acquisition rate | B5: 400000 | C5: 500000 | D5: 620000 | E5: +/-120k | F5: CRITICAL
A6: Dova retention / expansion | B6: 420000 | C6: 500000 | D6: 550000 | E6: +/-80k | F6: CRITICAL
A7: Navi-driven utilization lift timing | B7: 450000 | C7: 500000 | D7: 580000 | E7: +/-80k | F7: HIGH
A8: Avg deal size / rate realization | B8: 460000 | C8: 500000 | D8: 540000 | E8: +/-40k | F8: MED
A9: First hire ROI / timing | B9: 480000 | C9: 500000 | D9: 530000 | E9: +/-30k | F9: MED
A10: App product uptake (Opt only) | B10: 500000 | C10: 525000 | D10: 575000 | E10: +/-25k (Opt) | F10: LOW
A13: Recommendation: Focus execution on client acquisition system (powered by Navi CoS/Intel) and Dova relationship health above all. Phase 4 delivery is next highest leverage for capacity.

Sheet Balance_Sheet
A1: Simplified Balance Sheet Projection
A3: Item | B3: Y1 End | C3: Y2 End | D3: Y3 End
A4: Cash & Equiv | B4: 95000 | C4: 195000 | D4: 335000
A5: AR (est.) | B5: 25000 | C5: 35000 | D5: 45000
A6: Other Assets (minimal) | B6: 5000 | C6: 8000 | D6: 10000
A7: Total Assets | B7: =SUM(B4:B6) | C7: =SUM(C4:C6) | D7: =SUM(D4:D6)
A8: AP / Accrued (low) | B8: 8000 | C8: 10000 | D8: 12000
A9: Owner Equity / Retained | B9: =B7-B8 | C9: =C7-C8 | D9: =D7-D8
A10: Total Liab + Equity | B10: =B8+B9 | C10: =C8+C9 | D10: =D8+D9
